Workbook

Sheet Med
A1: Username | B1: Employee Id | C1: Designation | D1: Roles | E1: Units | F1: Department | G1: First Name | H1: Middle Name | I1: Last Name | J1: Phone | K1: Email Address | L1: Last Available At | M1: Enabled | N1: MultiFactor Authentication | O1: Third party/ AD username | P1: Timezone | Q1: Shift Duration | R1: Locations | S1: Reporting To
A2: Mohitv | B2: PT-PAT-06744 | D2: PRE 1 - Care from Nurses|Incident Reporter|QI Viewer|Incident Analyst|Audit User|PRE 1 - Nursing Services|Audit Incharge | E2: Paras Patna | F2: NURSING | L2: 24-Apr-2026 10:49 am | M2: Yes | N2: No
A3: preetamsaha | B3: PT-PAT-05069 | D3: Incident Reporter|QI Viewer|Incident Analyst|Audit User|Incident Admin|Audit Incharge|QI Admin | E3: Paras Patna | J3: 8017814192 | K3: quality.pat@parashospitals.com | L3: 24-Mar-2023 11:49 am | M3: No | N3: No
A4: jinubenny | B4: PT-PAT-03799 | D4: Incident Reporter|QI Viewer | E4: Paras Patna | F4: NURSING | J4: 7994723353 | K4: ns2pat@parashospitals.com | M4: Yes | N4: No
A5: shahinahmed | B5: PT-PAT-05111 | D5: Incident Reporter|QI Viewer|Audit User - Ambulance Response Time|Audit User - Patient Arrival Audit|Feedback Collector | E5: Paras Patna | F5: GUEST RELATIONS | J5: 7076114697 | K5: gre.patna@parashospitals.com | L5: 02-Jan-2024 05:08 pm | M5: No | N5: No
A6: SOMNATHMUKHARJEE | B6: pt-pat-05815 | D6: Feedback Duplicator|QI Viewer|PRE 0 - Staff Responsiveness and Behaviour|PRE 1 - Staff Responsiveness and Behaviour|PRE 1|Feedback Dashboard Viewer|PRE 1 - Paras Updates|Audit User - Patient Arrival Audit|Feedback Collector|PRE 0|Feedback Review Reassigner | E6: Paras Patna | F6: GUEST RELATIONS | J6: 8391917334 | K6: guestrelations.patna@parashospitals.com | L6: 03-Jun-2025 05:54 pm | M6: Yes | N6: No
A7: sanjooyadav | B7: PT-PAT-03787 | D7: Incident Reporter|QI Viewer | E7: Paras Patna | F7: NURSING | J7: 9670265111 | K7: ns1pat@parashospitals.com | M7: Yes | N7: No
A8: dhanjeetk | B8: PT-PAT-06941 | D8: Feedback Duplicator|QI Viewer|Feedback Leadership Dashboard Viewer|Feedback Dashboard Viewer|Audit User - Patient Arrival Audit|Feedback Collector|Guest Relations User | E8: Paras Patna | F8: HOSPITAL OPERATIONS | G8: Dhanjeet | I8: Kumar | J8: 7992430572 | K8: itpatna@parashospitals.com | L8: 22-May-2026 04:30 pm | M8: Yes | N8: No | Q8: ~-~
A9: kmgitanjalee | B9: PT-PAT-04187 | D9: Incident Reporter|QI Viewer | E9: Paras Patna | F9: NURSING | J9: 7275981209 | K9: nsgrpat@parashosiptals.com | M9: Yes | N9: No
A10: RAJEEVBHANDARI | B10: PT-PAT-05498 | D10: Incident Reporter|QI Viewer|Incident Analyst|Incident Dashboard Viewer|Audit Dashboard Viewer|Feedback Dashboard Viewer|PRE 3 | E10: Paras Patna | F10: HOSPITAL OPERATIONS | J10: 9031812313 | K10: zdpatna@parashospitals.com | L10: 15-May-2023 10:19 am | M10: No | N10: No
A11: sumansarikasinha | B11: PT-PAT-04047 | D11: Incident Reporter|QI Viewer | E11: Paras Patna | F11: NURSING | J11: 7870178723 | K11: ns5pat@parashospitals.com | M11: Yes | N11: No
A12: drsrinarayan | B12: PT-PAT-00231 | D12: Incident Reporter|QI Viewer|Incident Analyst|Audit Incharge - Prophylactic Antibiotic Compliance Audit|Audit Incharge - CPR Audit | E12: Paras Patna | F12: ANESTHESIOLOGY | J12: 9835293334 | K12: drsrirayan@parashospitals.com | M12: Yes | N12: No
A13: RitikN | B13: GG-GUR-10628 | D13: Incident Incharge|PRE 0 - Pharmacy|Incident Admin|PRE 1 - Pharmacy|PRE 2 - Pharmacy|Feedback Leadership Dashboard Viewer|PRE 3 - Pharmacy|Audit Dashboard Viewer|Incident Dashboard Viewer|Feedback Dashboard Viewer|Feedback Escalation Matrix Viewer|Audit User - Pharmacy Rejected Before GRN Audit | E13: Paras Patna | F13: OP PHARMACY|Pharmacy | G13: RITIK | I13: NAGAR | J13: 9350648327 | K13: ritik.nagar@parashospitals.com | L13: 26-May-2026 08:22 am | M13: Yes | N13: No | P13: Asia/Calcutta
A14: nehamehta | B14: PT-PAT-01399 | D14: Incident Reporter|QI Viewer | E14: Paras Patna | F14: NURSING | J14: 9835834915 | K14: ns4pat@parashospitals.com | L14: 22-Dec-2022 04:44 pm | M14: Yes | N14: No
A15: seemabaxla | B15: PT-PAT-03743 | D15: Incident Reporter|QI Viewer | E15: Paras Patna | F15: NURSING | J15: 7632922606 | K15: ns3pat@parashospitals.com | M15: Yes | N15: No
A16: rajishkr | B16: PT-PAT-05017 | D16: Incident Reporter|QI Viewer|Audit User | E16: Paras Patna | F16: NURSING | J16: 7003080165 | K16: nursing.supervisors@parashospitals.com | L16: 17-Feb-2023 08:40 pm | M16: Yes | N16: No
A17: ajmerikhatoon | B17: PT-PAT-04064 | D17: Incident Reporter|QI Viewer | E17: Paras Patna | F17: NURSING | J17: 7369807021 | K17: ns4pat@parashospitals.com | M17: Yes | N17: No
A18: adm_cell_PT | D18: QI Viewer|Incident Analyst|PRE 0 - Admission Experience | E18: Paras Patna | F18: Admissions | J18: 7283000915 | K18: it.his@parashospitals.com | M18: Yes | N18: No
A19: josphinmurmu | B19: PT-PAT-04998 | D19: Incident Reporter|QI Viewer | E19: Paras Patna | F19: NURSING | J19: 8178563377 | K19: ns5pat@parashospitals.com | M19: Yes | N19: No
A20: ROHANSHARMA | B20: PT-PAT-05351 | D20: Incident Reporter|QI Viewer|Audit User - Ambulance Response Time|Feedback Collector | E20: Paras Patna | J20: 7047680689 | K20: gre.pat@parashospitals.com | L20: 06-May-2023 01:32 pm | M20: No | N20: No
A21: RaviRanjanKumar | B21: PT-PAT-05681 | D21: QI Viewer|Incident Dashboard Viewer|Audit User - Adherence to safety precautions in Laboratory|Audit Incharge - Adherence to safety precautions in Laboratory|PRE 0 - Lab Services|PRE 1 - Lab Services|PRE 2 - Lab Services|PRE 3 - Lab Services | E21: Paras Patna | F21: Pathology | J21: 7631260747 | K21: raviranjan.kumar@parashospitals.com | L21: 15-Oct-2025 02:04 pm | M21: Yes | N21: No
A22: drkapilgarg | B22: drkapilgarg | D22: QI Viewer|Audit User|Incident Dashboard Viewer|Audit Dashboard Viewer|Feedback Dashboard Viewer | E22: Paras Patna | F22: GENERAL & ADMINISTRTIVE SERVICES | J22: 0000000000 | K22: it.his@parashospitals.com | L22: 31-Mar-2026 01:50 pm | M22: Yes | N22: No
A23: kalaivani | D23: Audit User|Audit Incharge|Audit Admin|Audit Configuration Admin|PRO|Incident Reporter|Incident Incharge|QI Viewer|Incident Analyst|QI Owner|Incident Admin|Hospital Statistics User|Hospital Statistics Admin|QI Admin | E23: Paras Patna | F23: GENERAL & ADMINISTRTIVE SERVICES | L23: 24-Jan-2025 12:34 pm | M23: Yes | N23: No
A24: ipd_sup_PT | D24: QI Viewer|Incident Analyst|PRE 0 - OPD Billing|PRE 0 - IPD Billing | E24: Paras Patna | F24: BILLING | J24: 08406001653 | K24: it.his@parashospitals.com | M24: Yes | N24: No
A25: sudhakarm | B25: PT-PAT-06791 | D25: PRE 2 - Dietician|Audit User|Audit Incharge|Feedback Dashboard Viewer|PRE 1 - Doctor Services|PRE 2 - Doctor Services|PRE 2 - Medical Equipment|Incident RCA Reviewer|QI Viewer|Incident Analyst|PRE 2 - ECG and ECHO|PRE 3 - ECG and ECHO|Hospital Statistics Admin - General Statistics|PRE 2 - Care from Doctors | E25: Paras Patna | F25: MEDICAL SERVICES | G25: Dr. Sudhakar Mishra | J25: 9939108739 | K25: drsudhakar.mishra@parashospitals.com | L25: 25-May-2026 10:21 am | M25: Yes | N25: No | Q25: ~-~
A26: arteekumari | B26: PT-PAT-04188 | D26: Incident Reporter|QI Viewer | E26: Paras Patna | F26: NURSING | J26: 9565918850 | K26: ns5pat@parashospitals.com | M26: Yes | N26: No
A27: rekhaemmanuel | B27: PT-PAT-04864 | D27: Incident Reporter|QI Viewer|Audit User | E27: Paras Patna | F27: NURSING | J27: 9631326070 | K27: ns2pat@parashospitals.com | L27: 17-May-2026 12:46 am | M27: Yes | N27: No
A28: arunkumar | B28: PT-PAT-04302 | D28: Incident Reporter|QI Viewer | E28: Paras Patna | F28: NURSING | J28: 9709928887 | K28: ns1pat@parashospitals.com | M28: Yes | N28: No
A29: rejeeshkumarr | B29: PT-PAT-02043 | D29: Incident Reporter|QI Viewer|Audit User | E29: Paras Patna | F29: NURSING | J29: 9947706363 | K29: nursing.supervisors@parashospitals.com | L29: 24-Jul-2023 12:54 pm | M29: Yes | N29: No
A30: syedarfiahmad | B30: PT-PAT-03327 | D30: Incident Reporter|QI Viewer | E30: Paras Patna | F30: NURSING | J30: 9015965427 | K30: ns4pat@parashospitals.com | M30: Yes | N30: No
A31: SONI.KUMARI | B31: PT-PAT-05900 | D31: Feedback Duplicator|QI Viewer|Audit User - Ambulance Response Time|PRE 0 - Staff Responsiveness and Behaviour|PRE 1 - Staff Responsiveness and Behaviour|PRE 1|Feedback Dashboard Viewer|PRE 1 - Paras Updates|Audit User - Patient Arrival Audit|Feedback Collector|PRE 0|Feedback Review Reassigner | E31: Paras Patna | F31: GUEST RELATIONS | J31: 8252749770 | K31: gre.pat@parashospitals.com | L31: 02-Mar-2024 03:46 pm | M31: Yes | N31: No
A32: NandiniGoswami | B32: pt-pat-05469 | D32: Feedback Duplicator|QI Viewer|PRE 0 - Staff Responsiveness and Behaviour|PRE 1 - Staff Responsiveness and Behaviour|PRE 1|Feedback Dashboard Viewer|PRE 1 - Paras Updates|Audit User - Patient Arrival Audit|Feedback Collector|PRE 0|Feedback Review Reassigner | E32: Paras Patna | J32: 7296079345 | L32: 04-May-2024 07:20 pm | M32: No | N32: No
A33: sabitadevi | B33: PT-PAT-00279 | D33: Incident Reporter|QI Viewer | E33: Paras Patna | F33: NURSING | J33: 9334429930 | K33: ns5pat@parashospitals.com | M33: Yes | N33: No
A34: jyotipandey | B34: PT-PAT-03864 | D34: Incident Reporter|QI Viewer | E34: Paras Patna | F34: NURSING | J34: 9792121998 | K34: ns4pat@parashospitals.com | M34: Yes | N34: No
A35: kumarijyoti | B35: PT-PAT-04241 | D35: Incident Reporter|QI Viewer | E35: Paras Patna | F35: NURSING | J35: 7897141280 | K35: ns1pat@parashospitals.com | M35: Yes | N35: No
A36: lokeshsingh | B36: GG-GUR-07852 | D36: Translator|Audit User|Audit Incharge|Audit Admin|Audit Configuration Admin|PRE 1|PRE 2|PRE 3|PRO|PRA|PRE 0|Guest Relations User|Feedback Review Reassigner|Feedback Configuration Admin|Incident Reporter|Incident Incharge|Incident Analyst|Incident Admin|Incident Advisor|Incident Officer|Incident Dashboard Viewer|Incident Configuration Admin|Audit User - Active file audit|Audit Incharge - Active file audit|Audit User - Call Bell Response Audit|Audit Incharge - Call Bell Response Audit|Audit User - TAT Adherence Audit|Audit Incharge - TAT Adherence Audit|Audit User - IPSG Audit|Audit Incharge - IPSG Audit|Audit User - HAPU Audit|Audit Incharge - HAPU Audit|Audit User - Ambulance Response Time|Audit Incharge - Ambulance Response Time|Audit User - Injection safety|Audit Incharge - Injection safety|Audit User - Prophylactic Antibiotic Compliance Audit|Audit Incharge - Prophylactic Antibiotic Compliance Audit|Audit User - Nursing Handover Audit|Audit Incharge - Nursing Handover Audit|Audit User - Nurse-Patient Ratio|Audit Incharge - Nurse-Patient Ratio|Audit User - Hand hygiene|Audit Incharge - Hand hygiene|Audit User - Passive file audit|Audit Incharge - Passive file audit|Audit User - Infusion safety|Audit Incharge - Infusion safety|Audit User - IP Prescription Audit|Audit Incharge - IP Prescription Audit|Audit User - Surgical safety checklist|Audit Incharge - Surgical safety checklist|Audit User - Biomedical Waste Management Audit|Audit Incharge - Biomedical Waste Management Audit|Audit User - Code Black - Mock drill|Audit Incharge - Code Black - Mock drill|Audit User - Critical Value Report Audit|Audit Incharge - Critical Value Report Audit|Audit User - CPR Audit|Audit Incharge - CPR Audit|Audit User - Patient identification|Audit Incharge - Patient identification|Audit User - Oral medication|Audit Incharge - Oral medication|Audit User - STROKE|Audit Incharge - STROKE|Audit User - Peer review of Imaging test report|Audit Incharge - Peer review of Imaging test report|Audit User - Code Hazmat - Mock drill|Audit Incharge - Code Hazmat - Mock drill|Audit User - Correlation with clinical diagnosis (Laboratory)|Audit Incharge - Correlation with clinical diagnosis (Laboratory)|Audit User - Pain Assessment Checklist|Audit Incharge - Pain Assessment Checklist|Audit User - Code Pink - Mock drill|Audit Incharge - Code Pink - Mock drill|Audit User - STEMI|Audit Incharge - STEMI|Audit User - Doctors Handover Audit|Audit Incharge - Doctors Handover Audit|Audit User - Adherence to safety precautions in Radiology / Cathlab / OT|Audit Incharge - Adherence to safety precautions in Radiology / Cathlab / OT|Audit User - SEPSIS PROTOCOL|Audit Incharge - SEPSIS PROTOCOL|Audit User - ER Prescription Audit|Audit Incharge - ER Prescription Audit|Audit User - Code Violet - Mock drill|Audit Incharge - Code Violet - Mock drill|Audit User - Drug Reconciliation Audit|Audit Incharge - Drug Reconciliation Audit|Audit User - CSSD Recall - Mock drill|Audit Incharge - CSSD Recall - Mock drill|Audit User - Code Red - Mock drill|Audit Incharge - Code Red - Mock drill|Audit User - Crash cart audit checklist|Audit Incharge - Crash cart audit checklist|Audit User - OP Prescription Audit|Audit Incharge - OP Prescription Audit|Audit User - Code Yellow - Mock drill|Audit Incharge - Code Yellow - Mock drill|Audit User - Correlation with clinical diagnosis (Radiology)|Audit Incharge - Correlation with clinical diagnosis (Radiology)|Audit User - Code Blue - Mock drill|Audit Incharge - Code Blue - Mock drill|Audit User - Adherence to safety precautions in Laboratory|Audit Incharge - Adherence to safety precautions in Laboratory|Audit User - TRAUMA Protocol|Audit Incharge - TRAUMA Protocol|PRE 0 - Diagnostics|PRE 1 - Diagnostics|PRE 2 - Diagnostics|PRE 3 - Diagnostics|PRE 0 - Admission Experience|PRE 1 - Admission Experience|PRE 2 - Admission Experience|PRE 3 - Admission Experience|Audit Dashboard Viewer|PRE 0 - Food Services and Dietician Rounds|PRE 1 - Food Services and Dietician Rounds|PRE 2 - Food Services and Dietician Rounds|PRE 3 - Food Services and Dietician Rounds|PRE 0 - Professional - Technical Competencies|PRE 1 - Professional - Technical Competencies|PRE 2 - Professional - Technical Competencies|PRE 3 - Professional - Technical Competencies|PRE 0 - Care from Nurses|PRE 1 - Care from Nurses|PRE 2 - Care from Nurses|PRE 3 - Care from Nurses|PRE 0 - Staff Responsiveness and Behaviour|PRE 1 - Staff Responsiveness and Behaviour|PRE 2 - Staff Responsiveness and Behaviour|PRE 3 - Staff Responsiveness and Behaviour|PRE 0 - Hospital Environment|PRE 1 - Hospital Environment|PRE 2 - Hospital Environment|PRE 3 - Hospital Environment|PRE 0 - Discharge Information|PRE 1 - Discharge Information|PRE 2 - Discharge Information|PRE 3 - Discharge Information|PRE 0 - Affective Support|PRE 1 - Affective Support|PRE 2 - Affective Support|PRE 3 - Affective Support|PRE 0 - Emergency Room Environment|PRE 1 - Emergency Room Environment|PRE 2 - Emergency Room Environment|PRE 3 - Emergency Room Environment|PRE 0 - Billing|PRE 1 - Billing|PRE 2 - Billing|PRE 3 - Billing|PRE 0 - Call Centre|PRE 1 - Call Centre|PRE 2 - Call Centre|PRE 3 - Call Centre|PRE 0 - ICU/CCU Care|PRE 1 - ICU/CCU Care|PRE 2 - ICU/CCU Care|PRE 3 - ICU/CCU Care|PRE 0 - Physiotherapy|PRE 1 - Physiotherapy|PRE 2 - Physiotherapy|PRE 3 - Physiotherapy|PRE 0 - Care from Doctors|PRE 1 - Care from Doctors|PRE 2 - Care from Doctors|PRE 3 - Care from Doctors|PRE 0 - Health Information|PRE 1 - Health Information|PRE 2 - Health Information|PRE 3 - Health Information|PRE 0 - Decisional Control|PRE 1 - Decisional Control|PRE 2 - Decisional Control|PRE 3 - Decisional Control|PRE 0 - Security Services|PRE 1 - Security Services|PRE 2 - Security Services|PRE 3 - Security Services|PRE 0 - Paras Updates|PRE 1 - Paras Updates|PRE 2 - Paras Updates|PRE 3 - Paras Updates|Audit User - Medication Audit|Audit Incharge - Medication Audit|Audit User - Phlebitis Audit|Audit Incharge - Phlebitis Audit|Audit User - NABH Safety Audit|Audit Incharge - NABH Safety Audit|Audit User - Clinical Safety Audit|Audit Incharge - Clinical Safety Audit|Hospital Statistics User|Hospital Statistics Admin|Hospital Statistics Configuration Admin|QI Admin|QI Configuration view|Hospital Statistics Admin - General Statistics|Hospital Statistics User - General Statistics|PRE 0 - IPD Billing|PRE 1 - IPD Billing|PRE 2 - IPD Billing|PRE 3 - IPD Billing|PRE 0 - Technology|PRE 1 - Technology|PRE 2 - Technology|PRE 3 - Technology|Feedback Collector|PRE 0 - Cleanliness|PRE 1 - Cleanliness|PRE 2 - Cleanliness|PRE 3 - Cleanliness|PRE 0 - Dietician|PRE 1 - Dietician|PRE 2 - Dietician|PRE 3 - Dietician|PRE 0 - Pharmacy|PRE 1 - Pharmacy|PRE 2 - Pharmacy|PRE 3 - Pharmacy|PRE 0 - Radiology or Lab Services|PRE 1 - Radiology or Lab Services|PRE 2 - Radiology or Lab Services|PRE 3 - Radiology or Lab Services|PRE 0 - Medical Equipment|PRE 1 - Medical Equipment|PRE 2 - Medical Equipment|PRE 3 - Medical Equipment|PRE 0 - Food and Beverage|PRE 1 - Food and Beverage|PRE 2 - Food and Beverage|PRE 3 - Food and Beverage|PRE 0 - GDA|PRE 1 - GDA|PRE 2 - GDA|PRE 3 - GDA|PRE 0 - Security|PRE 1 - Security|PRE 2 - Security|PRE 3 - Security|PRE 0 - OPD / ER Billing|PRE 1 - OPD / ER Billing|PRE 2 - OPD / ER Billing|PRE 3 - OPD / ER Billing|PRE 0 - Maintenance|PRE 1 - Maintenance|PRE 2 - Maintenance|PRE 3 - Maintenance|PRE 0 - Nursing Services|PRE 1 - Nursing Services|PRE 2 - Nursing Services|PRE 3 - Nursing Services|PRE 0 - Doctor Services|PRE 1 - Doctor Services|PRE 2 - Doctor Services|PRE 3 - Doctor Services|PRE 0 - Discharge|PRE 1 - Discharge|PRE 2 - Discharge|PRE 3 - Discharge|Incident RCA Approver|Incident RCA Reviewer|QI Viewer|QI Owner|Audit User - Nursing Documentation Audit|Audit Incharge - Nursing Documentation Audit|PRE 0 - GDA Services|PRE 1 - GDA Services|PRE 2 - GDA Services|PRE 3 - GDA Services|PRE 0 - Admission Process|PRE 1 - Admission Process|PRE 2 - Admission Process|PRE 3 - Admission Process|PRE 0 - Housekeeping Services|PRE 1 - Housekeeping Services|PRE 2 - Housekeeping Services|PRE 3 - Housekeeping Services|PRE 0 - Discharge Process|PRE 1 - Discharge Process|PRE 2 - Discharge Process|PRE 3 - Discharge Process|SLA and Configurations Viewer|User Account Manager|Feedback Dashboard Viewer|PRE 0 - Radiology Services|PRE 1 - Radiology Services|PRE 2 - Radiology Services|PRE 3 - Radiology Services|PRE 0 - Lab Services|PRE 1 - Lab Services|PRE 2 - Lab Services|PRE 3 - Lab Services|Feedback Duplicator|Audit User - CLABSI Bundle Audit|Audit Incharge - CLABSI Bundle Audit|Audit User - CAUTI Bundle Audit|Audit Incharge - CAUTI Bundle Audit|Audit User - VAE Bundle Audit|Audit Incharge - VAE Bundle Audit|Botomate Viewer|Audit User - Patient Arrival Audit|Audit Incharge - Patient Arrival Audit|Non-Conformance Reporter|Non-Conformance Admin|Non-Conformance Champion|Non-Conformance Officer|Non-Conformance Configuration Admin|Hospital Statistics Admin - Admission TAT Statistics|Hospital Statistics User - Admission TAT Statistics|Hospital Statistics Admin - Discharge TAT Statistics|Hospital Statistics User - Discharge TAT Statistics|Hospital Statistics Admin - OPD TAT Statistics|Hospital Statistics User - OPD TAT Statistics|Feedback Leadership Dashboard Viewer|Survey Viewer|Survey Owner|Survey Admin|Feedback Escalation Matrix Viewer|Audit Escalation Matrix|Hospital Stats Escalation Matrix|Hospital Statistics Admin - Pharmacy Statistics|Hospital Statistics User - Pharmacy Statistics|Hospital Statistics Admin - ICU Statistics|Hospital Statistics User - ICU Statistics|Hospital Statistics Admin - Operating Theatre Statistics|Hospital Statistics User - Operating Theatre Statistics|Hospital Statistics Admin - Emergency Department Statistics|Hospital Statistics User - Emergency Department Statistics|Hospital Statistics Admin - Ethics Committee Statistics|Hospital Statistics User - Ethics Committee Statistics|Hospital Statistics Admin - Blood Bank statistics|Hospital Statistics User - Blood Bank statistics|Hospital Statistics Admin - Cathlab Statistics|Hospital Statistics User - Cathlab Statistics|Hospital Statistics Admin - Radiology Statistics|Hospital Statistics User - Radiology Statistics|Hospital Statistics Admin - Infection control Statistics|Hospital Statistics User - Infection control Statistics|Hospital Statistics Admin - Laboratory Statistics|Hospital Statistics User - Laboratory Statistics|Hospital Statistics Admin - HR Statistics|Hospital Statistics User - HR Statistics|Non-Conformance Reporter - Admission and Discharge|Non-Conformance Admin - Admission and Discharge|Non-Conformance Reporter - Operation Theatre|Non-Conformance Admin - Operation Theatre|Non-Conformance Reporter - ICU|Non-Conformance Admin - ICU|Non-Conformance Reporter - Blood Bank|Non-Conformance Admin - Blood Bank|Non-Conformance Reporter - Laboratory|Non-Conformance Admin - Laboratory|Non-Conformance Reporter - Radiology|Non-Conformance Admin - Radiology|Non-Conformance Reporter - Emergency|Non-Conformance Admin - Emergency|Non-Conformance Reporter - Pharmacy|Non-Conformance Admin - Pharmacy|Non-Conformance Reporter - tres|Non-Conformance Admin - tres|Audit User - Return to emergency within 72 hrs with similar complaints Audit|Audit Incharge - Return to emergency within 72 hrs with similar complaints Audit|Audit User - Blood Wastage Audit|Audit Incharge - Blood Wastage Audit|Audit User - Unplanned discharges Audit|Audit Incharge - Unplanned discharges Audit|Audit User - Readmission to Hospital within 48 Hours Audit|Audit Incharge - Readmission to Hospital within 48 Hours Audit|Audit User - Unplanned Ventilation following Anaesthesia Audit|Audit Incharge - Unplanned Ventilation following Anaesthesia Audit|Audit User - Pharmacy Local Purchase Audit|Audit Incharge - Pharmacy Local Purchase Audit|Audit User - Radiology Re-do Audit|Audit Incharge - Radiology Re-do Audit|Audit User - Radiology Imaging Modality Change Audit|Audit Incharge - Radiology Imaging Modality Change Audit|Audit User - Blood Bank Under Collection Audit|Audit Incharge - Blood Bank Under Collection Audit|Audit User - Readmission to ICU within 48 Hours Audit|Audit Incharge - Readmission to ICU within 48 Hours Audit|Audit User - Laboratory Culture Contamination Audit|Audit Incharge - Laboratory Culture Contamination Audit|Audit User - Blood Bank Re-do Audit|Audit Incharge - Blood Bank Re-do Audit|Audit User - Blood Bank Reagent Stock out Audit|Audit Incharge - Blood Bank Reagent Stock out Audit|Audit User - Pharmacy Rejected Before GRN Audit|Audit Incharge - Pharmacy Rejected Before GRN Audit|Audit User - Blood Bank Reporting error Audit|Audit Incharge - Blood Bank Reporting error Audit|Audit User - Modification of Anesthesia plan Audit|Audit Incharge - Modification of Anesthesia plan Audit|Audit User - Unplanned return to Operation Theatre Audit|Audit Incharge - Unplanned return to Operation Theatre Audit|Audit User - Rescheduling or Cancellation of surgeries Audit|Audit Incharge - Rescheduling or Cancellation of surgeries Audit|Audit User - Pharmacy Stock Out Audit|Audit Incharge - Pharmacy Stock Out Audit|Audit User - Intra-Operative change in Surgery Audit|Audit Incharge - Intra-Operative change in Surgery Audit|Audit User - Unplanned Post-Operative Admission to Surgical ICU Audit|Audit Incharge - Unplanned Post-Operative Admission to Surgical ICU Audit|Audit User - Pharmacy Variations in Procurement Process Audit|Audit Incharge - Pharmacy Variations in Procurement Process Audit|Audit User - Laboratory Sample Rejection Audit|Audit Incharge - Laboratory Sample Rejection Audit|Audit User - Laboratory Re-do Audit|Audit Incharge - Laboratory Re-do Audit|Audit User - High TAT for issuing or receiving blood from blood-bank Audit|Audit Incharge - High TAT for issuing or receiving blood from blood-bank Audit|Hospital Statistics Admin - Nurse Patient Ratio Statistics|Hospital Statistics User - Nurse Patient Ratio Statistics|Call Center reviewer|Hospital Statistics Admin - POS|Hospital Statistics User - POS|Hospital Statistics Admin - Quality Statistics|Hospital Statistics User - Quality Statistics|Hospital Statistics Admin - security Stats|Hospital Statistics User - security Stats|Audit User - Multi-Disciplinary Tumor Board - MDT|Audit Incharge - Multi-Disciplinary Tumor Board - MDT|PRE 0 - ECG and ECHO|PRE 1 - ECG and ECHO|PRE 2 - ECG and ECHO|PRE 3 - ECG and ECHO|PRE 0 - OPD Billing|PRE 1 - OPD Billing|PRE 2 - OPD Billing|PRE 3 - OPD Billing|Audit User - Spill Kit Checklist|Audit Incharge - Spill Kit Checklist|Audit User - HAZMAT AUDIT CHECKLIST|Audit Incharge - HAZMAT AUDIT CHECKLIST|Audit User - Pre and Post Procedure Financial Counselling|Audit Incharge - Pre and Post Procedure Financial Counselling|Audit User - Counselling or Briefing About The Room Services|Audit Incharge - Counselling or Briefing About The Room Services|Audit User - RRT Mockdrill - Mock drill|Audit Incharge - RRT Mockdrill - Mock drill|Audit User - RRT Mockdrill Audit|Audit Incharge - RRT Mockdrill Audit|Audit User - Code Orange - Mock drill|Audit Incharge - Code Orange - Mock drill | E36: Paras Patna | F36: INFORMATION TECHNOLOGY|IT | J36: 8800764545 | K36: lokesh.singh@parashospitals.com | L36: 25-May-2026 05:46 pm | M36: Yes | N36: No
A37: kumaripriyanka | B37: PT-PAT-04257 | D37: Incident Reporter|QI Viewer | E37: Paras Patna | F37: NURSING | J37: 8004050087 | K37: ns3pat@parashospitals.com | M37: Yes | N37: No
A38: abhishekkumarsharma | B38: PT-PAT-04697 | D38: Incident Reporter|QI Viewer|Incident Analyst|PRE 1 - Staff Responsiveness and Behaviour | E38: Paras Patna | J38: 8827478250 | K38: abhishek.sharma@parashospitals.com | M38: No | N38: No
A39: mubashhir | D39: QI Viewer|Audit User|Audit Admin|Audit Configuration Admin | E39: Paras Patna | F39: GENERAL & ADMINISTRTIVE SERVICES | L39: 10-Mar-2025 04:35 pm | M39: Yes | N39: No
A40: kumarianamikasinha | B40: PT-PAT-00921 | D40: Incident Reporter|QI Viewer | E40: Paras Patna | F40: NURSING | J40: 9852575665 | K40: nsgrpat@parashosiptals.com | M40: Yes | N40: No
...

Sheet Paras
A1: Sr. NO | B1: userName | C1: password | D1: departments | E1: roles | F1: units | G1: locations | H1: Mail ID | I1: Personal Phone | J1: employeeId | K1: Reporting To | L1: Category Code | M1: Designation Name | N1: Date Of Joining | O1: Phone | P1: E_ID | Q1: Mail
A2: 1 | B2: Shivangi | C2: Paras@123 | D2: Respiratory ICU | E2: INCIDENT REPORTER | F2: Paras HMRI Patna | G2: Patna | H2: ranishivangi9199@gmail.com | I2: 9199023328 | J2: PT-PA05897 | K2: Neha Mehta | L2: Nursing | M2: Staff Nurse | N2: 45281 | O2: =INDEX(Med!J:J,MATCH(Paras!I2,Med!J:J,0)) -> #N/A | P2: =INDEX(Med!B:B,MATCH(Paras!J2,Med!B:B,0)) -> #N/A | Q2: =INDEX(Med!K:K,MATCH(Paras!H2,Med!K:K,0)) -> #N/A
A3: 2 | B3: Divya Yadav | C3: Paras@123 | D3: Emergency | E3: INCIDENT REPORTER | F3: Paras HMRI Patna | G3: Patna | H3: dilipyadav199091@gmail.com | I3: 7905497275 | J3: PT-PA05899 | K3: Onkar Mani Tirpathi | L3: Nursing | M3: Sr. Staff Nurse | N3: 45282 | O3: =INDEX(Med!J:J,MATCH(Paras!I3,Med!J:J,0)) -> #N/A | P3: =INDEX(Med!B:B,MATCH(Paras!J3,Med!B:B,0)) -> #N/A | Q3: =INDEX(Med!K:K,MATCH(Paras!H3,Med!K:K,0)) -> #N/A
A4: 3 | B4: Priyasmita Chattapadhyay | C4: Paras@123 | D4: Guest Relations | E4: INCIDENT REPORTER | F4: Paras HMRI Patna | G4: Patna | H4: priyasmitactjee888@gmail.com | I4: 8240873293 | J4: PT-PA05901 | K4: Ramavtar Jangid | L4: Support | M4: Sr. Executive- Level 1 | N4: 45288 | O4: =INDEX(Med!J:J,MATCH(Paras!I4,Med!J:J,0)) -> 8240873293 | P4: =INDEX(Med!B:B,MATCH(Paras!J4,Med!B:B,0)) -> #N/A | Q4: =INDEX(Med!K:K,MATCH(Paras!H4,Med!K:K,0)) -> #N/A
A5: 4 | B5: Nishant singh | C5: Paras@123 | D5: Neurology | E5: INCIDENT REPORTER | F5: Paras HMRI Patna | G5: Patna | H5: nishantsingh19@gmail.com | I5: 7903950921 | J5: PT-PA05902 | K5: Manish Kumar | L5: Doctors | M5: DNB Primary - 1 | N5: 45288 | O5: =INDEX(Med!J:J,MATCH(Paras!I5,Med!J:J,0)) -> #N/A | P5: =INDEX(Med!B:B,MATCH(Paras!J5,Med!B:B,0)) -> #N/A | Q5: =INDEX(Med!K:K,MATCH(Paras!H5,Med!K:K,0)) -> #N/A
A6: 5 | B6: Sujay Ranjan | C6: Paras@123 | D6: Nephrology | E6: INCIDENT REPORTER | F6: Paras HMRI Patna | G6: Patna | H6: sujaynmch@gmail.com | I6: 9430559937 | J6: PT-PA05904 | K6: Manish Kumar | L6: Doctors | M6: DNB Primary - 1 | N6: 45293 | O6: =INDEX(Med!J:J,MATCH(Paras!I6,Med!J:J,0)) -> #N/A | P6: =INDEX(Med!B:B,MATCH(Paras!J6,Med!B:B,0)) -> #N/A | Q6: =INDEX(Med!K:K,MATCH(Paras!H6,Med!K:K,0)) -> #N/A
A7: 6 | B7: Prem Chandra Kumar | C7: Paras@123 | D7: Dispatch | E7: INCIDENT REPORTER | F7: Paras HMRI Patna | G7: Patna | H7: PREMPARASHMRI@GMAIL.COM | I7: 6202743641 | J7: PT-PAT-00035 | K7: Shailesh Mauar | L7: Administration | M7: Office Assistant- Level 1 | N7: 41426 | O7: =INDEX(Med!J:J,MATCH(Paras!I7,Med!J:J,0)) -> #N/A | P7: =INDEX(Med!B:B,MATCH(Paras!J7,Med!B:B,0)) -> #N/A | Q7: =INDEX(Med!K:K,MATCH(Paras!H7,Med!K:K,0)) -> #N/A
A8: 7 | B8: Abhishek | C8: Paras@123 | D8: Neurology | E8: INCIDENT REPORTER | F8: Paras HMRI Patna | G8: Patna | H8: drabhishek.kumar@parashospitals.com | I8: 9431432955 | J8: PT-PAT-00109 | K8: Anil Kumar | L8: Doctors | M8: Senior Consultant | N8: 41456 | O8: =INDEX(Med!J:J,MATCH(Paras!I8,Med!J:J,0)) -> #N/A | P8: =INDEX(Med!B:B,MATCH(Paras!J8,Med!B:B,0)) -> #N/A | Q8: =INDEX(Med!K:K,MATCH(Paras!H8,Med!K:K,0)) -> #N/A
A9: 8 | B9: Bineeta Sinha | C9: Paras@123 | D9: Clinical Pathology | E9: INCIDENT REPORTER | F9: Paras HMRI Patna | G9: Patna | H9: drbineeta.sinha@parashospitals.com | I9: 7858888175 | J9: PT-PAT-00110 | K9: Anil Kumar | L9: Doctors | M9: Principal Consultant | N9: 41456 | O9: =INDEX(Med!J:J,MATCH(Paras!I9,Med!J:J,0)) -> #N/A | P9: =INDEX(Med!B:B,MATCH(Paras!J9,Med!B:B,0)) -> #N/A | Q9: =INDEX(Med!K:K,MATCH(Paras!H9,Med!K:K,0)) -> #N/A
A10: 9 | B10: Masihullah | C10: Paras@123 | D10: MAMBS | E10: INCIDENT REPORTER | F10: Paras HMRI Patna | G10: Patna | H10: drmashiullah@parashospitals.com | I10: 9835848120 | J10: PT-PAT-00113 | K10: Manish Kumar | L10: Doctors | M10: Associate Director | N10: 41456 | O10: =INDEX(Med!J:J,MATCH(Paras!I10,Med!J:J,0)) -> #N/A | P10: =INDEX(Med!B:B,MATCH(Paras!J10,Med!B:B,0)) -> #N/A | Q10: =INDEX(Med!K:K,MATCH(Paras!H10,Med!K:K,0)) -> #N/A
A11: 10 | B11: Gautam Ram Babu Prasad | C11: Paras@123 | D11: Ortho Spine Surgery | E11: INCIDENT REPORTER | F11: Paras HMRI Patna | G11: Patna | H11: careforspine@yahoo.com | I11: 8877667722 | J11: PT-PAT-00122 | K11: Anil Kumar | L11: Revenue Generating Doctors | M11: Associate Director | N11: 41487 | O11: =INDEX(Med!J:J,MATCH(Paras!I11,Med!J:J,0)) -> #N/A | P11: =INDEX(Med!B:B,MATCH(Paras!J11,Med!B:B,0)) -> #N/A | Q11: =INDEX(Med!K:K,MATCH(Paras!H11,Med!K:K,0)) -> #N/A
A12: 11 | B12: Jibi Varghese | C12: Paras@123 | D12: Nursing Administration | E12: INCIDENT REPORTER | F12: Paras HMRI Patna | G12: Patna | H12: Jibijosejace@Gmail.Com | I12: 7654346060 | J12: PT-PAT-00152 | K12: Subhra Ghatak | L12: Nursing | M12: Manager | N12: 41457 | O12: =INDEX(Med!J:J,MATCH(Paras!I12,Med!J:J,0)) -> 7654346060 | P12: =INDEX(Med!B:B,MATCH(Paras!J12,Med!B:B,0)) -> PT-PAT-00152 | Q12: =INDEX(Med!K:K,MATCH(Paras!H12,Med!K:K,0)) -> #N/A
A13: 12 | B13: Vinod K Thakur | C13: Paras@123 | D13: Joint Replacement Surgery | E13: INCIDENT REPORTER | F13: Paras HMRI Patna | G13: Patna | H13: drvinodkrthakur@gmail.com | I13: 9431041154 | J13: PT-PAT-00197 | K13: Anil Kumar | L13: Revenue Generating Doctors | M13: Associate Director | N13: 41487 | O13: =INDEX(Med!J:J,MATCH(Paras!I13,Med!J:J,0)) -> #N/A | P13: =INDEX(Med!B:B,MATCH(Paras!J13,Med!B:B,0)) -> #N/A | Q13: =INDEX(Med!K:K,MATCH(Paras!H13,Med!K:K,0)) -> #N/A
... A39: 38 | B39: Ahmad Abdul Hai | C39: Paras@123 | D39: MAMBS | E39: INCIDENT REPORTER | F39: Paras HMRI Patna | G39: Patna | H39: draahai@parashospitals.com | I39: 9304972834 | J39: PT-PAT-00465 | K39: Anil Kumar | L39: Doctors | M39: Director | N39: 41487 | O39: =INDEX(Med!J:J,MATCH(Paras!I39,Med!J:J,0)) -> #N/A | P39: =INDEX(Med!B:B,MATCH(Paras!J39,Med!B:B,0)) -> #N/A | Q39: =INDEX(Med!K:K,MATCH(Paras!H39,Med!K:K,0)) -> #N/A
A40: 39 | B40: John Mukhopadhyay | C40: Paras@123 | D40: Joint Replacement Surgery | E40: INCIDENT REPORTER | F40: Paras HMRI Patna | G40: Patna | H40: drjhon@parashospitals.com | J40: PT-PAT-00466 | K40: Anil Kumar | L40: Revenue Generating Doctors | M40: Director | N40: 41487 | O40: =INDEX(Med!J:J,MATCH(Paras!I40,Med!J:J,0)) -> #N/A | P40: =INDEX(Med!B:B,MATCH(Paras!J40,Med!B:B,0)) -> #N/A | Q40: =INDEX(Med!K:K,MATCH(Paras!H40,Med!K:K,0)) -> #N/A
A41: 40 | B41: Rajiv Ranjan | C41: Paras@123 | D41: Paediatrics | E41: INCIDENT REPORTER | F41: Paras HMRI Patna | G41: Patna | H41: drrajivranjan@yahoo.com | I41: 9801835440 | J41: PT-PAT-00483 | K41: Anil Kumar | L41: Doctors | M41: Senior Consultant | N41: 41533 | O41: =INDEX(Med!J:J,MATCH(Paras!I41,Med!J:J,0)) -> #N/A | P41: =INDEX(Med!B:B,MATCH(Paras!J41,Med!B:B,0)) -> #N/A | Q41: =INDEX(Med!K:K,MATCH(Paras!H41,Med!K:K,0)) -> #N/A
A42: 41 | B42: Md. Moshirul Islam Khan | C42: Paras@123 | D42: General OT | E42: INCIDENT REPORTER | F42: Paras HMRI Patna | G42: Patna | H42: mikhan286@gmail.com | I42: 9308897408 | J42: PT-PAT-00564 | K42: Neha Singh | L42: Paramedics | M42: Sr. Technician - Level 1 | N42: 41557 | O42: =INDEX(Med!J:J,MATCH(Paras!I42,Med!J:J,0)) -> #N/A | P42: =INDEX(Med!B:B,MATCH(Paras!J42,Med!B:B,0)) -> #N/A | Q42: =INDEX(Med!K:K,MATCH(Paras!H42,Med!K:K,0)) -> #N/A
A43: 42 | B43: Anjani Mehra | C43: Paras@123 | D43: Neuro Surgical ICU | E43: INCIDENT REPORTER | F43: Paras HMRI Patna | G43: Patna | H43: dranjanimehra091@gmail.com | I43: 9507008008 | J43: PT-PAT-00698 | K43: Manish Kumar | L43: Doctors | M43: Attending Consultant | N43: 41628 | O43: =INDEX(Med!J:J,MATCH(Paras!I43,Med!J:J,0)) -> #N/A | P43: =INDEX(Med!B:B,MATCH(Paras!J43,Med!B:B,0)) -> #N/A | Q43: =INDEX(Med!K:K,MATCH(Paras!H43,Med!K:K,0)) -> #N/A
A44: 43 | B44: Ravi Bhaskar | C44: Paras@123 | D44: IP Pharmacy | E44: INCIDENT REPORTER | F44: Paras HMRI Patna | G44: Patna | H44: acmailmetest@gmail.com | I44: 7004320579 | J44: PT-PAT-00714 | K44: Arbind Prasad | L44: Paramedics | M44: Sr. Pharmacist - Level 1 | N44: 41575 | O44: =INDEX(Med!J:J,MATCH(Paras!I44,Med!J:J,0)) -> #N/A | P44: =INDEX(Med!B:B,MATCH(Paras!J44,Med!B:B,0)) -> #N/A | Q44: =INDEX(Med!K:K,MATCH(Paras!H44,Med!K:K,0)) -> #N/A
A45: 44 | B45: Avinash Kumar Singh | C45: Paras@123 | D45: Haemato Oncology & BMT | E45: INCIDENT REPORTER | F45: Paras HMRI Patna | G45: Patna | H45: avanish.kumar@parashospitals.com | I45: 9960945860 | J45: PT-PAT-00727 | K45: Anil Kumar | L45: Revenue Generating Doctors | M45: Director | N45: 41641 | O45: =INDEX(Med!J:J,MATCH(Paras!I45,Med!J:J,0)) -> #N/A | P45: =INDEX(Med!B:B,MATCH(Paras!J45,Med!B:B,0)) -> #N/A | Q45: =INDEX(Med!K:K,MATCH(Paras!H45,Med!K:K,0)) -> #N/A
A46: 45 | B46: Mazharul Haque | C46: Paras@123 | D46: Bio Chemistry | E46: INCIDENT REPORTER | F46: Paras HMRI Patna | G46: Patna | H46: mazharulhaque71@gmail.com | I46: 7903281806 | J46: PT-PAT-00729 | K46: Ravi Ranjan Kumar | L46: Paramedics | M46: Sr. Technician - Level 2 | N46: 41641 | O46: =INDEX(Med!J:J,MATCH(Paras!I46,Med!J:J,0)) -> #N/A | P46: =INDEX(Med!B:B,MATCH(Paras!J46,Med!B:B,0)) -> #N/A | Q46: =INDEX(Med!K:K,MATCH(Paras!H46,Med!K:K,0)) -> #N/A
A47: 46 | B47: Sushil Kumar | C47: Paras@123 | D47: Endoscopy | E47: INCIDENT REPORTER | F47: Paras HMRI Patna | G47: Patna | H47: kumarsunil1111@gmail.com | I47: 9955569687 | J47: PT-PAT-00768 | K47: Manish Kumar | L47: Paramedics | M47: Technician - Level 1 | N47: 41655 | O47: =INDEX(Med!J:J,MATCH(Paras!I47,Med!J:J,0)) -> #N/A | P47: =INDEX(Med!B:B,MATCH(Paras!J47,Med!B:B,0)) -> #N/A | Q47: =INDEX(Med!K:K,MATCH(Paras!H47,Med!K:K,0)) -> #N/A
A48: 47 | B48: Rufina Kispotta | C48: Paras@123 | D48: CCU | E48: INCIDENT REPORTER | F48: Paras HMRI Patna | G48: Patna | H48: Rufinakispotta074@Gmail.Com | I48: 7781866326 | J48: PT-PAT-00788 | K48: Archana Chandra | L48: Nursing | M48: Sr. Staff Nurse | N48: 41663 | O48: =INDEX(Med!J:J,MATCH(Paras!I48,Med!J:J,0)) -> 7781866326 | P48: =INDEX(Med!B:B,MATCH(Paras!J48,Med!B:B,0)) -> PT-PAT-00788 | Q48: =INDEX(Med!K:K,MATCH(Paras!H48,Med!K:K,0)) -> #N/A
A49: 48 | B49: Md. Khurshid Alam | C49: Paras@123 | D49: General OT | E49: INCIDENT REPORTER | F49: Paras HMRI Patna | G49: Patna | H49: khurshid.alam2010@yahoo.com | I49: 9155581676 | J49: PT-PAT-00937 | K49: Neha Singh | L49: Paramedics | M49: Senior Supervisor | N49: 41739 | O49: =INDEX(Med!J:J,MATCH(Paras!I49,Med!J:J,0)) -> #N/A | P49: =INDEX(Med!B:B,MATCH(Paras!J49,Med!B:B,0)) -> #N/A | Q49: =INDEX(Med!K:K,MATCH(Paras!H49,Med!K:K,0)) -> #N/A
A50: 49 | B50: Satish Srivastava | C50: Paras@123 | D50: Coordinator Pool | E50: INCIDENT REPORTER | F50: Paras HMRI Patna | G50: Patna | H50: satish.bstdc@gmail.com | I50: 8002150150 | J50: PT-PAT-00950 | K50: Ramavtar Jangid | L50: Administration | M50: Deputy Manager | N50: 41744 | O50: =INDEX(Med!J:J,MATCH(Paras!I50,Med!J:J,0)) -> #N/A | P50: =INDEX(Med!B:B,MATCH(Paras!J50,Med!B:B,0)) -> #N/A | Q50: =INDEX(Med!K:K,MATCH(Paras!H50,Med!K:K,0)) -> #N/A
A51: 50 | B51: CHANDAN KUMAR JHA | C51: Paras@123 | D51: Blood Bank | E51: INCIDENT REPORTER | F51: Paras HMRI Patna | G51: Patna | H51: CANDANJHA1985@GMAIL.COM | I51: 6201482174 | J51: PT-PAT-01042 | K51: Syed Md. Shamsheer Ahmad | L51: Paramedics | M51: Sr. Technician - Level 1 | N51: 41792 | O51: =INDEX(Med!J:J,MATCH(Paras!I51,Med!J:J,0)) -> #N/A | P51: =INDEX(Med!B:B,MATCH(Paras!J51,Med!B:B,0)) -> #N/A | Q51: =INDEX(Med!K:K,MATCH(Paras!H51,Med!K:K,0)) -> #N/A
A52: 51 | B52: Amresh Kumar | C52: Paras@123 | D52: Neurology | E52: INCIDENT REPORTER | F52: Paras HMRI Patna | G52: Patna | H52: amreshkumar5186@gmail.com | I52: 7766021111 | J52: PT-PAT-01134 | K52: Manish Kumar | L52: Doctors | M52: Senior Medical Officer | N52: 41848 | O52: =INDEX(Med!J:J,MATCH(Paras!I52,Med!J:J,0)) -> #N/A | P52: =INDEX(Med!B:B,MATCH(Paras!J52,Med!B:B,0)) -> #N/A | Q52: =INDEX(Med!K:K,MATCH(Paras!H52,Med!K:K,0)) -> #N/A
... A318: 317 | B318: Vivek Kumar | C318: Paras@123 | D318: Blood Bank | E318: INCIDENT REPORTER | F318: Paras HMRI Patna | G318: Patna | H318: VIVEKLUMAR012796@GMAIL.COM | I318: 8227957463 | J318: PT-PAT-06055 | K318: Syed Md. Shamsheer Ahmad | L318: Paramedics | M318: Technician - Level 1 | N318: 45425 | O318: =INDEX(Med!J:J,MATCH(Paras!I318,Med!J:J,0)) -> #N/A | P318: =INDEX(Med!B:B,MATCH(Paras!J318,Med!B:B,0)) -> #N/A | Q318: =INDEX(Med!K:K,MATCH(Paras!H318,Med!K:K,0)) -> #N/A
A319: 318 | B319: Anil Kumar | C319: Paras@123 | D319: Hospital Operations | E319: INCIDENT REPORTER | F319: Paras HMRI Patna | G319: Patna | H319: kumar.anil@parashospitals.com | I319: 9950067666 | J319: PT-PAT-06060 | L319: Administration | M319: Zonal Director | N319: 45434 | O319: =INDEX(Med!J:J,MATCH(Paras!I319,Med!J:J,0)) -> #N/A | P319: =INDEX(Med!B:B,MATCH(Paras!J319,Med!B:B,0)) -> #N/A | Q319: =INDEX(Med!K:K,MATCH(Paras!H319,Med!K:K,0)) -> #N/A
A320: 319 | B320: Neeraj Sinha | C320: Paras@123 | D320: Endocrinology | E320: INCIDENT REPORTER | F320: Paras HMRI Patna | G320: Patna | H320: dr.neerajsinha@gmail.com | I320: 9748718138 | J320: PT-PAT-06063 | K320: Anil Kumar | L320: Revenue Generating Doctors | M320: Senior Consultant | N320: 45444 | O320: =INDEX(Med!J:J,MATCH(Paras!I320,Med!J:J,0)) -> #N/A | P320: =INDEX(Med!B:B,MATCH(Paras!J320,Med!B:B,0)) -> #N/A | Q320: =INDEX(Med!K:K,MATCH(Paras!H320,Med!K:K,0)) -> #N/A
A321: 320 | B321: Ramavtar Jangid | C321: Paras@123 | D321: Front Office | E321: INCIDENT REPORTER | F321: Paras HMRI Patna | G321: Patna | H321: ramavtar.jangid@parashospitals.com | I321: 9587112029 | J321: PT-PAT-06064 | K321: Anil Kumar | L321: Support | M321: General Manager | N321: 45476 | O321: =INDEX(Med!J:J,MATCH(Paras!I321,Med!J:J,0)) -> #N/A | P321: =INDEX(Med!B:B,MATCH(Paras!J321,Med!B:B,0)) -> #N/A | Q321: =INDEX(Med!K:K,MATCH(Paras!H321,Med!K:K,0)) -> #N/A
A322: 321 | B322: Payal Pandey | C322: Paras@123 | D322: Sales & Marketing | E322: INCIDENT REPORTER | F322: Paras HMRI Patna | G322: Patna | H322: payal.pandey@parashospitals.com | I322: 7091819078 | J322: PT-PAT-06065 | K322: Rohit Kumar | L322: Administration | M322: Assistant Manager | N322: 45476 | O322: =INDEX(Med!J:J,MATCH(Paras!I322,Med!J:J,0)) -> #N/A | P322: =INDEX(Med!B:B,MATCH(Paras!J322,Med!B:B,0)) -> #N/A | Q322: =INDEX(Med!K:K,MATCH(Paras!H322,Med!K:K,0)) -> #N/A
A323: 322 | B323: Shivam Kumar | C323: Paras@123 | D323: Domestic Sales | E323: INCIDENT REPORTER | F323: Paras HMRI Patna | G323: Patna | H323: shivamsingh22295@gmail.com | I323: 7908835002 | J323: PT-PAT-06066 | K323: Rohit Kumar | L323: Administration | M323: Manager | N323: 45476 | O323: =INDEX(Med!J:J,MATCH(Paras!I323,Med!J:J,0)) -> #N/A | P323: =INDEX(Med!B:B,MATCH(Paras!J323,Med!B:B,0)) -> #N/A | Q323: =INDEX(Med!K:K,MATCH(Paras!H323,Med!K:K,0)) -> #N/A
A324: 323 | B324: Ranu Kumar | C324: Paras@123 | D324: Domestic Sales | E324: INCIDENT REPORTER | F324: Paras HMRI Patna | G324: Patna | H324: ranubhardwaj2846@gmail.com | I324: 9905769823 | J324: PT-PAT-06067 | K324: Rohit Kumar | L324: Administration | M324: Assistant Manager | N324: 45477 | O324: =INDEX(Med!J:J,MATCH(Paras!I324,Med!J:J,0)) -> #N/A | P324: =INDEX(Med!B:B,MATCH(Paras!J324,Med!B:B,0)) -> #N/A | Q324: =INDEX(Med!K:K,MATCH(Paras!H324,Med!K:K,0)) -> #N/A
A325: 324 | B325: Vishal Anand | C325: Paras@123 | D325: IP Pharmacy | E325: INCIDENT REPORTER | F325: Paras HMRI Patna | G325: Patna | H325: vishalanand2222@gmail.com | I325: 6205754459 | J325: PT-PAT-06068 | K325: Arbind Prasad | L325: Paramedics | M325: Sr. Pharmacist - Level 1 | N325: 45478 | O325: =INDEX(Med!J:J,MATCH(Paras!I325,Med!J:J,0)) -> #N/A | P325: =INDEX(Med!B:B,MATCH(Paras!J325,Med!B:B,0)) -> #N/A | Q325: =INDEX(Med!K:K,MATCH(Paras!H325,Med!K:K,0)) -> #N/A
A326: 325 | B326: Ratnesh Raj | C326: Paras@123 | D326: OP Pharmacy | E326: INCIDENT REPORTER | F326: Paras HMRI Patna | G326: Patna | H326: rajratnesh89@gmail.com | I326: 9973044800 | J326: PT-PAT-06069 | K326: Arbind Prasad | L326: Paramedics | M326: Pharmacist - Level 1 | N326: 45478 | O326: =INDEX(Med!J:J,MATCH(Paras!I326,Med!J:J,0)) -> #N/A | P326: =INDEX(Med!B:B,MATCH(Paras!J326,Med!B:B,0)) -> #N/A | Q326: =INDEX(Med!K:K,MATCH(Paras!H326,Med!K:K,0)) -> #N/A
A327: 326 | B327: Pallab Pati | C327: Paras@123 | D327: Radiation Oncology | E327: INCIDENT REPORTER | F327: Paras HMRI Patna | G327: Patna | H327: pallabpati8@gmail.com | I327: 8250667262 | J327: PT-PAT-06074 | K327: Jesu Jackin Lawrence | L327: Paramedics | M327: Sr. Technician - Level 1 | N327: 45495 | O327: =INDEX(Med!J:J,MATCH(Paras!I327,Med!J:J,0)) -> #N/A | P327: =INDEX(Med!B:B,MATCH(Paras!J327,Med!B:B,0)) -> #N/A | Q327: =INDEX(Med!K:K,MATCH(Paras!H327,Med!K:K,0)) -> #N/A
A328: 327 | B328: Harendra Kumar Singh | C328: Paras@123 | D328: Billing | E328: INCIDENT REPORTER | F328: Paras HMRI Patna | G328: Patna | H328: harendrakumar@singh@parashospitals.com | I328: 9811404042 | J328: PT-PAT-06078 | K328: Ramavtar Jangid | L328: Administration | M328: Sr. Manager | N328: 45499 | O328: =INDEX(Med!J:J,MATCH(Paras!I328,Med!J:J,0)) -> #N/A | P328: =INDEX(Med!B:B,MATCH(Paras!J328,Med!B:B,0)) -> #N/A | Q328: =INDEX(Med!K:K,MATCH(Paras!H328,Med!K:K,0)) -> #N/A
A329: 328 | B329: Neeraj Kumar | C329: Paras@123 | D329: Accounts | E329: INCIDENT REPORTER | F329: Paras HMRI Patna | G329: Patna | H329: neeraj.kumar@parashospitals.com | I329: 9810870948 | J329: PT-PAT-06079 | K329: Anil Kumar | L329: Administration | M329: Deputy General Manager | N329: 45500 | O329: =INDEX(Med!J:J,MATCH(Paras!I329,Med!J:J,0)) -> #N/A | P329: =INDEX(Med!B:B,MATCH(Paras!J329,Med!B:B,0)) -> PT-PAT-06079 | Q329: =INDEX(Med!K:K,MATCH(Paras!H329,Med!K:K,0)) -> neeraj.kumar@parashospitals.com
A330: 329 | B330: Firoj Alam | C330: Paras@123 | D330: Medical Surgical Ward | E330: INCIDENT REPORTER | F330: Paras HMRI Patna | G330: Patna | H330: Falam2688@Gmail.Com | I330: 7033067294 | J330: PT-PAT-06086 | K330: Minakshi Pandey | L330: Nursing | M330: Staff Nurse | N330: 45502 | O330: =INDEX(Med!J:J,MATCH(Paras!I330,Med!J:J,0)) -> #N/A | P330: =INDEX(Med!B:B,MATCH(Paras!J330,Med!B:B,0)) -> #N/A | Q330: =INDEX(Med!K:K,MATCH(Paras!H330,Med!K:K,0)) -> #N/A
...

Sheet existing
A1: Sr. NO | B1: userName | C1: password | D1: departments | E1: roles | F1: Exising_role | G1: units | H1: locations | I1: Mail ID | J1: Personal Phone | K1: employeeId | L1: Reporting To | M1: Category Code | N1: Designation Name | O1: Date Of Joining
A2: 3 | B2: Priyasmita Chattapadhyay | C2: Paras@123 | D2: Guest Relations | E2: INCIDENT REPORTER | F2: Incident Reporter|Feedback Duplicator|QI Viewer|PRE 0 - Staff Responsiveness and Behaviour|PRE 1 - Staff Responsiveness and Behaviour|PRE 1|Feedback Dashboard Viewer|PRE 1 - Paras Updates|Audit User - Patient Arrival Audit|Feedback Collector|PRE 0|Feedback Review Reassigner | G2: Paras HMRI Patna | H2: Patna | I2: priyasmitactjee888@gmail.com | J2: 8240873293 | K2: PT-PA05901 | L2: Ramavtar Jangid | M2: Support | N2: Sr. Executive- Level 1 | O2: 45288
A3: 11 | B3: Jibi Varghese | C3: Paras@123 | D3: Nursing Administration | E3: INCIDENT REPORTER | F3: Incident Reporter|PRE 1 - Care from Nurses|QI Viewer|Incident Analyst|Audit User|Audit Incharge|PRE 1 - Nursing Services | G3: Paras HMRI Patna | H3: Patna | I3: Jibijosejace@Gmail.Com | J3: 7654346060 | K3: PT-PAT-00152 | L3: Subhra Ghatak | M3: Nursing | N3: Manager | O3: 41457
A4: 15 | B4: Srinarayan | C4: Paras@123 | D4: General Anaesthesia | E4: INCIDENT REPORTER | F4: Incident Reporter|QI Viewer|Incident Analyst|Audit Incharge - Prophylactic Antibiotic Compliance Audit|Audit Incharge - CPR Audit | G4: Paras HMRI Patna | H4: Patna | I4: srinarayan45@gmail.com | J4: 9835293334 | K4: PT-PAT-00231 | L4: Anil Kumar | M4: Doctors | N4: Principal Consultant | O4: 41465
A5: 17 | B5: Abhishek Kumar | C5: Paras@123 | D5: Coordinator Pool | E5: INCIDENT REPORTER | F5: Incident Reporter|QI Viewer|Incident Analyst|Audit User|Audit Incharge|PRE 2 - Admission Process|PRE 2 - Admission Experience|PRE 2 - Call Centre|PRE 2 - OPD / ER Billing | G5: Paras HMRI Patna | H5: Patna | I5: kumar.abhishek@parashospitals.com | J5: 8252672281 | K5: PT-PAT-00244 | L5: Ramavtar Jangid | M5: Administration | N5: Sr. Manager | O5: 41466
A6: 22 | B6: Meena Goswami | C6: Paras@123 | D6: Ortho OT | E6: INCIDENT REPORTER | F6: Incident Reporter|QI Viewer | G6: Paras HMRI Patna | H6: Patna | I6: meena123@gmail.com | J6: 9631995901 | K6: PT-PAT-00278 | L6: Neha Singh | M6: Nursing | N6: Trainee Staff Nurse | O6: 41477
A7: 47 | B7: Rufina Kispotta | C7: Paras@123 | D7: CCU | E7: INCIDENT REPORTER | F7: Incident Reporter|QI Viewer | G7: Paras HMRI Patna | H7: Patna | I7: Rufinakispotta074@Gmail.Com | J7: 7781866326 | K7: PT-PAT-00788 | L7: Archana Chandra | M7: Nursing | N7: Sr. Staff Nurse | O7: 41663
A8: 52 | B8: Syed Md. Shamsheer Ahmad | C8: Paras@123 | D8: Blood Bank | E8: INCIDENT REPORTER | F8: Audit User|Audit Incharge|Audit Admin|Feedback Leadership Dashboard Viewer|Feedback Dashboard Viewer|Incident Level 3 approver|Incident RCA Approver|Incident RCA Reviewer|Incident Incharge|Incident Analyst|Incident Admin|Incident Advisor|Incident Officer|Incident Dashboard Viewer|Feedback Collector | G8: Paras HMRI Patna | H8: Patna | I8: Shamsheer1988@gmail.com | J8: 9905724241 | K8: PT-PAT-01163 | L8: Manish Kumar | M8: Paramedics | N8: Deputy Manager | O8: 41857
A9: 58 | B9: Suchita Kujur | C9: Paras@123 | D9: OPD | E9: INCIDENT REPORTER | F9: Incident Reporter|QI Viewer | G9: Paras HMRI Patna | H9: Patna | I9: suchitakujur41@gmail.com | J9: 8102201940 | K9: PT-PAT-01347 | L9: Durgabati Kumari | M9: Nursing | N9: Trainee Staff Nurse | O9: 41976
A10: 62 | B10: Neha Mehta | C10: Paras@123 | D10: Respiratory ICU | E10: INCIDENT REPORTER | F10: Incident Reporter|QI Viewer | G10: Paras HMRI Patna | H10: Patna | I10: nehamehta3131@gmail.com | J10: 9835834915 | K10: PT-PAT-01399 | L10: Jibi Varghese | M10: Nursing | N10: Ward Incharge | O10: 41989
A11: 65 | B11: Sunita Kisku | C11: Paras@123 | D11: OPD | E11: INCIDENT REPORTER | F11: Incident Reporter|QI Viewer | G11: Paras HMRI Patna | H11: Patna | I11: SUNITAKISKU311289@GMAIL.COM | J11: 9546618442 | K11: PT-PAT-01467 | L11: Durgabati Kumari | M11: Nursing | N11: Trainee Staff Nurse | O11: 42072
A12: 73 | B12: Harendra Kumar Divakar | C12: Paras@123 | D12: Medical Record Room | E12: INCIDENT REPORTER | F12: Incident Reporter|QI Viewer|Incident Analyst|Hospital Statistics Admin - General Statistics|Hospital Statistics User - General Statistics|Hospital Statistics User - Quality Statistics|Audit User - Passive file audit | G12: Paras HMRI Patna | H12: Patna | I12: Harendra_Hm003@Yahoo.Co.In | J12: 9631412647 | K12: PT-PAT-01824 | L12: Manish Kumar | M12: Paramedics | N12: Deputy Manager | O12: 42296
A13: 74 | B13: Sandhya Kumari | C13: Paras@123 | D13: OPD | E13: INCIDENT REPORTER | F13: Incident Reporter|QI Viewer | G13: Paras HMRI Patna | H13: Patna | I13: sandhya1712@gmail.com | J13: 7654636608 | K13: PT-PAT-01933 | L13: Durgabati Kumari | M13: Nursing | N13: Trainee Staff Nurse | O13: 42357
... A46: 601 | B46: Vishal Kumar | C46: Paras@123 | D46: Biomedical Engineering | E46: INCIDENT REPORTER | F46: Incident Reporter|QI Viewer | G46: Paras HMRI Patna | H46: Patna | I46: BIOMEDICAL.PATNA@PARASHOSPITALS.COM | J46: 6207474258 | K46: PT-PAT-06819 | L46: Dharmendra Kumar | M46: Support | N46: Engineer- Level 1 | O46: 45931
A47: 667 | B47: Mohd Shahabuddin | C47: Paras@123 | D47: Engineering & Maintenance | E47: INCIDENT REPORTER | F47: PRE 1 - Maintenance|QI Viewer|PRE 2 - Maintenance|PRE 3 - Maintenance|Feedback Leadership Dashboard Viewer|Feedback Dashboard Viewer|PRE 1|PRE 2|PRE 3|PRE 0|PRE 0 - Maintenance | G47: Paras HMRI Patna | H47: Patna | J47: 9911077433 | K47: PT-PAT-06922 | L47: Ramavtar Jangid | M47: Support | N47: Deputy Manager | O47: 45992
A48: 689 | B48: Amit Kumar Aman | C48: Paras@123 | D48: Security | E48: INCIDENT REPORTER | F48: QI Viewer|PRE 0 - Security Services|PRE 1 - Security Services|PRE 0 - Security|PRE 1 - Security|Hospital Statistics User - security Stats | G48: Paras HMRI Patna | H48: Patna | J48: 7303402503 | K48: PT-PAT-06954 | L48: Jasmer Singh | M48: Support | N48: Manager | O48: 46007
A49: 703 | B49: Subhra Ghatak | C49: Paras@123 | D49: Nursing Administration | E49: INCIDENT REPORTER | F49: Incident Reporter|PRE 1 - Care from Nurses|PRE 2 - Care from Nurses|QI Viewer|Incident Analyst|Audit User|Audit Incharge|PRE 1 - Nursing Services|PRE 2 - Nursing Services | G49: Paras HMRI Patna | H49: Patna | J49: 8240613095 | K49: PT-PAT-06971 | L49: Manish Kumar | M49: Nursing | N49: Associate General Manager | O49: 46015
A50: 835 | B50: Prashant Sen | C50: Paras@123 | D50: Hospital Operations | E50: INCIDENT REPORTER | F50: Incident Reporter|QI Viewer|Incident Analyst|Audit Incharge|Feedback Dashboard Viewer|PRE 2|Audit User - Patient Arrival Audit|Feedback Collector|Feedback Review Reassigner | G50: Paras HMRI Patna | H50: Patna | I50: p8789singh@gmail.com | J50: 7061163204 | K50: PT-PAT-07119 | L50: Ramavtar Jangid | M50: Administration | N50: Assistant Manager | O50: 46113
A51: 852 | B51: Hari Shanker | C51: Paras@123 | D51: Cardiothoracic and Vascular Surgery | E51: INCIDENT REPORTER | F51: Incident Reporter|QI Viewer | G51: Paras HMRI Patna | H51: Patna | I51: hari.pandey0@gmail.com | J51: 7000948243 | K51: PT-PAT-07137 | L51: Manish Kumar | M51: Paramedics | N51: Physician Assistant - Level 1 | O51: 46118
A52: 328 | B52: Neeraj Kumar | C52: Paras@123 | D52: Accounts | E52: INCIDENT REPORTER | F52: Incident Reporter|QI Viewer|Incident Analyst|Audit User|Audit Incharge | G52: Paras HMRI Patna | H52: Patna | I52: neeraj.kumar@parashospitals.com | J52: 9810870948 | K52: PT-PAT-06079 | L52: Anil Kumar | M52: Administration | N52: Deputy General Manager | O52: 45500
A53: 19 | B53: Baby Nisha | C53: Paras@123 | D53: Ortho OT | E53: INCIDENT REPORTER | F53: Incident Reporter|QI Viewer | G53: Paras HMRI Patna | H53: Patna | I53: Babyxnisha@Gmail.Com | J53: 9279735483 | K53: PT-PAT-00272 | L53: Neha Singh | M53: Nursing | N53: Trainee Staff Nurse | O53: 41477
A54: 23 | B54: Sabita Devi | C54: Paras@123 | D54: Ortho OT | E54: INCIDENT REPORTER | F54: Incident Reporter|QI Viewer | G54: Paras HMRI Patna | H54: Patna | I54: sabitabharti2004@gmail.com | J54: 9304465035 | K54: PT-PAT-00279 | L54: Neha Singh | M54: Nursing | N54: Trainee Staff Nurse | O54: 41477
A55: 57 | B55: Seema Bara | C55: Paras@123 | D55: MICU | E55: INCIDENT REPORTER | F55: Incident Reporter|QI Viewer | G55: Paras HMRI Patna | H55: Patna | I55: seemabara1340@gmail.com | J55: 7541988044 | K55: PT-PAT-01340 | L55: Jibi Varghese | M55: Nursing | N55: Nurse Incharge | O55: 41974
A56: 59 | B56: Suby Paul | C56: Paras@123 | D56: Nursing Administration | E56: INCIDENT REPORTER | F56: Incident Reporter|QI Viewer | G56: Paras HMRI Patna | H56: Patna | I56: Suby010@Gmail.Com | J56: 9162927034 | K56: PT-PAT-01362 | L56: Jibi Varghese | M56: Nursing | N56: Supervisor | O56: 41986
A57: 64 | B57: Srimati Gope | C57: Paras@123 | D57: Nursing Administration | E57: INCIDENT REPORTER | F57: Incident Reporter|QI Viewer|Audit User | G57: Paras HMRI Patna | H57: Patna | I57: srimati@gmail.com | J57: 8809868887 | K57: PT-PAT-01463 | L57: Jibi Varghese | M57: Nursing | N57: Supervisor | O57: 42066
A58: 100 | B58: Archana Chandra | C58: Paras@123 | D58: CCU | E58: INCIDENT REPORTER | F58: Incident Reporter|QI Viewer | G58: Paras HMRI Patna | H58: Patna | I58: Archanachandra95@Gmail.Com | J58: 9896375231 | K58: PT-PAT-02803 | L58: Jibi Varghese | M58: Nursing | N58: Ward Incharge | O58: 43054
A59: 139 | B59: Bijendra Yadav | C59: Paras@123 | D59: Pre & Post Operations | E59: INCIDENT REPORTER | F59: Incident Reporter|QI Viewer | G59: Paras HMRI Patna | H59: Patna | I59: bijendra10196@gmail.com | J59: 8102578832 | K59: PT-PAT-04166 | L59: Manisha Kumari | M59: Nursing | N59: Staff Nurse | O59: 44120
A60: 141 | B60: Onkar Mani Tirpathi | C60: Paras@123 | D60: Emergency | E60: INCIDENT REPORTER | F60: Incident Reporter|QI Viewer | G60: Paras HMRI Patna | H60: Patna | I60: onkarmanitripathi25756@gmail.com | J60: 8858659783 | K60: PT-PAT-04194 | L60: Jibi Varghese | M60: Nursing | N60: Sr. Staff Nurse | O60: 44133
A61: 550 | B61: Mohit Verma | C61: Paras@123 | D61: Nursing Administration | E61: INCIDENT REPORTER | F61: PRE 1 - Care from Nurses|Incident Reporter|QI Viewer|Incident Analyst|Audit User|PRE 1 - Nursing Services|Audit Incharge | G61: Paras HMRI Patna | H61: Patna | I61: mohitv9550@gmail.com | J61: 9855751498 | K61: PT-PAT-06744 | L61: Subhra Ghatak | M61: Nursing | N61: Assistant Manager | O61: 45887

Sheet New_User
A1: Sr. NO | B1: userName | C1: password | D1: departments | E1: roles | F1: units | G1: locations | H1: Mail ID | I1: Personal Phone | J1: employeeId | K1: Reporting To | L1: Category Code | M1: Designation Name | N1: Date Of Joining
A2: 1 | B2: shivangi | C2: Paras@123 | D2: Respiratory ICU | E2: Incident Reporter | F2: Paras HMRI Patna | G2: Patna | H2: ranishivangi9199@gmail.com | I2: 9199023328 | J2: PT-PA05897 | K2: Neha Mehta | L2: Nursing | M2: Staff Nurse | N2: 45281
A3: 2 | B3: divyayadav | C3: Paras@123 | D3: EMERGENCY | E3: Incident Reporter | F3: Paras HMRI Patna | G3: Patna | H3: dilipyadav199091@gmail.com | I3: 7905497275 | J3: PT-PA05899 | K3: Onkar Mani Tirpathi | L3: Nursing | M3: Sr. Staff Nurse | N3: 45282
A4: 4 | B4: nishantsingh | C4: Paras@123 | D4: NEUROLOGY | E4: Incident Reporter | F4: Paras HMRI Patna | G4: Patna | H4: nishantsingh19@gmail.com | I4: 7903950921 | J4: PT-PA05902 | K4: Manish Kumar | L4: Doctors | M4: DNB Primary - 1 | N4: 45288
A5: 5 | B5: sujayranjan | C5: Paras@123 | D5: NEPHROLOGY | E5: Incident Reporter | F5: Paras HMRI Patna | G5: Patna | H5: sujaynmch@gmail.com | I5: 9430559937 | J5: PT-PA05904 | K5: Manish Kumar | L5: Doctors | M5: DNB Primary - 1 | N5: 45293
A6: 6 | B6: premchandrakumar | C6: Paras@123 | D6: DISPATCH CENTER | E6: Incident Reporter | F6: Paras HMRI Patna | G6: Patna | H6: PREMPARASHMRI@GMAIL.COM | I6: 6202743641 | J6: PT-PAT-00035 | K6: Shailesh Mauar | L6: Administration | M6: Office Assistant- Level 1 | N6: 41426
A7: 7 | B7: abhishek | C7: Paras@123 | D7: NEUROLOGY | E7: Incident Reporter | F7: Paras HMRI Patna | G7: Patna | H7: drabhishek.kumar@parashospitals.com | I7: 9431432955 | J7: PT-PAT-00109 | K7: Anil Kumar | L7: Doctors | M7: Senior Consultant | N7: 41456
A8: 8 | B8: bineetasinha | C8: Paras@123 | D8: Pathology | E8: Incident Reporter | F8: Paras HMRI Patna | G8: Patna | H8: drbineeta.sinha@parashospitals.com | I8: 7858888175 | J8: PT-PAT-00110 | K8: Anil Kumar | L8: Doctors | M8: Principal Consultant | N8: 41456
A9: 9 | B9: masihullah | C9: Paras@123 | D9: MAMBS | E9: Incident Reporter | F9: Paras HMRI Patna | G9: Patna | H9: drmashiullah@parashospitals.com | I9: 9835848120 | J9: PT-PAT-00113 | K9: Manish Kumar | L9: Doctors | M9: Associate Director | N9: 41456
A10: 10 | B10: gautamrambabuprasad | C10: Paras@123 | D10: ORTHOPEDICS | E10: Incident Reporter | F10: Paras HMRI Patna | G10: Patna | H10: careforspine@yahoo.com | I10: 8877667722 | J10: PT-PAT-00122 | K10: Anil Kumar | L10: Revenue Generating Doctors | M10: Associate Director | N10: 41487
A11: 12 | B11: vinodkthakur | C11: Paras@123 | D11: ORTHOPEDICS | E11: Incident Reporter | F11: Paras HMRI Patna | G11: Patna | H11: drvinodkrthakur@gmail.com | I11: 9431041154 | J11: PT-PAT-00197 | K11: Anil Kumar | L11: Revenue Generating Doctors | M11: Associate Director | N11: 41487
A12: 13 | B12: rahulgarg | C12: Paras@123 | D12: NEUROLOGY | E12: Incident Reporter | F12: Paras HMRI Patna | G12: Patna | H12: rahul.garg5551@gmail.com | I12: 9334385551 | J12: PT-PAT-00219 | K12: Manish Kumar | L12: Paramedics | M12: Sr. Technician - Level 1 | N12: 41465
A13: 14 | B13: shekarkeshri | C13: Paras@123 | D13: ONCOLOGY | E13: Incident Reporter | F13: Paras HMRI Patna | G13: Patna | H13: drshekhar.keshri@parashospitals.com | I13: 9973043603 | J13: PT-PAT-00230 | K13: Anil Kumar | L13: Doctors | M13: Director | N13: 41465
... A32: 38 | B32: ahmadabdulhai | C32: Paras@123 | D32: MAMBS | E32: Incident Reporter | F32: Paras HMRI Patna | G32: Patna | H32: draahai@parashospitals.com | I32: 9304972834 | J32: PT-PAT-00465 | K32: Anil Kumar | L32: Doctors | M32: Director | N32: 41487
A33: 39 | B33: johnmukhopadhyay | C33: Paras@123 | D33: ORTHOPEDICS | E33: Incident Reporter | F33: Paras HMRI Patna | G33: Patna | H33: drjhon@parashospitals.com | J33: PT-PAT-00466 | K33: Anil Kumar | L33: Revenue Generating Doctors | M33: Director | N33: 41487
A34: 40 | B34: rajivranjan | C34: Paras@123 | D34: PEDIATRICS | E34: Incident Reporter | F34: Paras HMRI Patna | G34: Patna | H34: drrajivranjan@yahoo.com | I34: 9801835440 | J34: PT-PAT-00483 | K34: Anil Kumar | L34: Doctors | M34: Senior Consultant | N34: 41533
A35: 41 | B35: mdmoshirulislamkhan | C35: Paras@123 | D35: OT | E35: Incident Reporter | F35: Paras HMRI Patna | G35: Patna | H35: mikhan286@gmail.com | I35: 9308897408 | J35: PT-PAT-00564 | K35: Neha Singh | L35: Paramedics | M35: Sr. Technician - Level 1 | N35: 41557
A36: 42 | B36: anjanimehra | C36: Paras@123 | D36: NEUROLOGY | E36: Incident Reporter | F36: Paras HMRI Patna | G36: Patna | H36: dranjanimehra091@gmail.com | I36: 9507008008 | J36: PT-PAT-00698 | K36: Manish Kumar | L36: Doctors | M36: Attending Consultant | N36: 41628
A37: 43 | B37: ravibhaskar | C37: Paras@123 | D37: Pharmacy | E37: Incident Reporter | F37: Paras HMRI Patna | G37: Patna | H37: acmailmetest@gmail.com | I37: 7004320579 | J37: PT-PAT-00714 | K37: Arbind Prasad | L37: Paramedics | M37: Sr. Pharmacist - Level 1 | N37: 41575
A38: 44 | B38: avinashkumarsingh | C38: Paras@123 | D38: HEMATOLOGY | E38: Incident Reporter | F38: Paras HMRI Patna | G38: Patna | H38: avanish.kumar@parashospitals.com | I38: 9960945860 | J38: PT-PAT-00727 | K38: Anil Kumar | L38: Revenue Generating Doctors | M38: Director | N38: 41641
A39: 45 | B39: mazharulhaque | C39: Paras@123 | D39: Biochemistry | E39: Incident Reporter | F39: Paras HMRI Patna | G39: Patna | H39: mazharulhaque71@gmail.com | I39: 7903281806 | J39: PT-PAT-00729 | K39: Ravi Ranjan Kumar | L39: Paramedics | M39: Sr. Technician - Level 2 | N39: 41641
